Workbook

Sheet PRODUCTOS GENERALES PEYBU 
A1: Code | B1: Name | C1: Cod. Familia / Departamento | D1: Cant. Inventario | E1: Cod. Unidad | F1: Min | G1: Max | H1: Cost | I1: Bar Code | J1: Reorder Point | K1: R. Qty | L1: Waste | M1: Cod. Warehouse | N1: Presentacion del proveedor | O1: Costo Proveedor | P1: Producto Final? (Si,No) | Q1: Precio Venta | R1: Impuesto Item | S1: Cod. Categoria Item | T1: Cod. Item | U1: Cod. Autor | V1: Cod. Colección | W1: Activo? (Si/No) | X1: Descripcion | Y1: Precio Especial | Z1: Caracteristica1 | AA1: Venta Online Ecommerce? (Si/No) | AB1: Nombre de Imagen | AC1: Unidad de Inventario de Producto | AE1: RECEPCION INCIAL
A2: PEY01 | B2: Bolsa plana flexible 43x41 | C2: Empaques | E2: Unidad | H2: 1580 | M2: W100 | N2: Unidad | O2: 12000 | AC2: Unidad | AD2: 10 l | AE2: ALMACEN-COMPRAS
A3: PEY02 | B3: bolsa planaflexible 32x36 | C3: Empaques | E3: Unidad | H3: 1382 | M3: W100 | N3: Unidad | O3: 8000 | P3: No | AC3: Unidad | AD3: 5 l | AE3: ALMACEN-COMPRAS
A4: PEY03 | B4: bolsa para empacar hueso | C4: Empaques | E4: Unidad | H4: 750 | M4: W100 | N4: Unidad | O4: 20000 | P4: SI | AC4: Unidad | AE4: ALMACEN-COMPRAS
A5: PEY04 | B5: Bolsa capucha canastilla | C5: Otros | E5: Unidad | H5: 400 | M5: W100 | N5: Unidad | O5: 25000 | P5: No | AC5: Unidad | AE5: ALMACEN-COMPRAS
A6: PEY05 | B6: Bolsa Jumbo basura verde | C6: Otros | E6: Unidad | H6: 1580 | M6: W100 | N6: Unidad | O6: 18500 | P6: No | AC6: Unidad | AE6: ALMACEN-COMPRAS
A7: PEY06 | B7: Bolsa jumbo bausra negra | C7: Otros | E7: Unidad | H7: 1580 | M7: W100 | N7: Unidad | O7: 12000 | P7: No | AC7: Unidad | AE7: ALMACEN-COMPRAS
A8: PEY07 | B8: Rollo Industrial Cocina | C8: Otros | E8: Unidad | H8: 104000 | M8: W100 | N8: Unidad | O8: 12000 | P8: No | AC8: Unidad | AE8: ALMACEN-COMPRAS
A9: PEY08 | B9: bolsa jumbo blanca | C9: Otros | E9: Unidad | H9: 1580 | M9: W100 | N9: Unidad | O9: 50000 | P9: No | AC9: Unidad | AE9: ALMACEN-COMPRAS
A10: PEY09 | B10: bolsa baño negra | C10: Otros | E10: Unidad | H10: 1580 | M10: W100 | N10: Unidad | O10: 50000 | P10: No | AC10: Unidad | AE10: ALMACEN-COMPRAS
A11: PEY10 | B11: Tortillas Trigo 16 cm | C11: Cereales y harinas | E11: Unidad | H11: 645 | M11: W100 | N11: Unidad | O11: 12000 | P11: No | AC11: Unidad | AE11: PUNTOS DE VENTA
A12: PEY11 | B12: Tortillas Maíz 11x40 | C12: Cereales y harinas | E12: Unidad | H12: 300 | M12: W100 | N12: Unidad | O12: 2000 | P12: No | AC12: Unidad | AE12: ROGELIOS Y EVENTOS
A13: PEY12 | B13: Queso doblecrema | C13: lacteos | E13: Gramos | H13: 22.6 | M13: W100 | N13: Gramos | O13: 1000 | P13: No | AC13: Gramos | AE13: AUTOCAR Y EVENTOS
A14: PEY13 | B14: Tortillas Trigo 12 cm | C14: Cereales y harinas | E14: Unidad | H14: 642 | M14: W100 | N14: Unidad | AC14: Unidad | AE14: AUTOCAR Y EVENTOS
A15: PEY14 | B15: Tortillas Trigo 22 cm | C15: Cereales y harinas | E15: Unidad | H15: 900 | M15: W100 | N15: Unidad | AC15: Unidad | AE15: AUTOCAR Y EVENTOS
A16: PEY15 | B16: Tortillas fresca Maíz 11x32 autocar | C16: Cereales y harinas | E16: Unidad | H16: 350 | M16: W100 | N16: Unidad | AC16: Unidad | AE16: AUTOCAR Y EVENTOS
A17: PEY16 | B17: cebolla morada | C17: Vegetales y Hortalizas | E17: Gramos | H17: 6 | M17: W100 | N17: Gramos | AC17: Gramos | AE17: ROGELIOS Y EVENTOS
A18: PEY17 | B18: Cilantro | C18: Vegetales y Hortalizas | E18: Gramos | H18: 8.5 | M18: W100 | N18: Gramos | AC18: Gramos | AE18: TODOS LOS PUNTOS
A19: PEY18 | B19: Limón Taithy | C19: Vegetales y Hortalizas | E19: Gramos | H19: 5 | M19: W100 | N19: Gramos | AC19: Gramos | AE19: TODOS LOS PUNTOS
A20: PEY19 | B20: Pimenton mixto | C20: Vegetales y Hortalizas | E20: Gramos | H20: 10 | M20: W100 | N20: Gramos | AC20: Gramos | AE20: AUTOCAR Y PLANTA
A21: PEY20 | B21: cebolla blanca | C21: Vegetales y Hortalizas | E21: Gramos | H21: 6 | M21: W100 | N21: Gramos | AC21: Gramos | AE21: AUTOCAR Y PLANTA
A22: PEY21 | B22: Piña | C22: Vegetales y Hortalizas | E22: Gramos | H22: 10 | M22: W100 | N22: Gramos | AC22: Gramos | AE22: AUTOCAR
A23: PEY22 | B23: Tabasco | C23: Especias y condimentos | E23: mililitro | H23: 130 | M23: W100 | N23: mililitro | AC23: mililitro | AE23: ROGELIOS Y EVENTOS
A24: PEY23 | B24: salsa ingelsa fresh | C24: Especias y condimentos | E24: mililitro | H24: 40.677966 | M24: W100 | N24: mililitro | AC24: mililitro | AE24: ROGELIOS Y EVENTOS
A25: PEY24 | B25: sal de chamoy | C25: Especias y condimentos | E25: Gramos | H25: 48.6 | M25: W100 | N25: Gramos | AC25: Gramos | AE25: ROGELIOS Y EVENTOS
... A27: PEY26 | B27: Basukazo | C27: Especias y condimentos | E27: Unidad | H27: 1200 | M27: W100 | N27: Unidad | AC27: Unidad | AE27: ROGELIO
A28: PEY27 | B28: Agua Botella | C28: Bebidas gaseosificadas | E28: Unidad | H28: 1200 | M28: W100 | N28: Unidad | AC28: Unidad
A29: PEY28 | B29: Cerveza Lata | C29: Bebidas gaseosificadas | E29: Unidad | H29: 2820 | M29: W100 | N29: Unidad | AC29: Unidad
A30: PEY29 | B30: Gaseosas Pet | C30: Bebidas gaseosificadas | E30: Unidad | H30: 2500 | M30: W100 | N30: Unidad | AC30: Unidad
A31: PEY30 | B31: Bolsa scraf cubiertos | C31: Empaques | E31: Unidad | H31: 44.03 | M31: W100 | N31: Unidad | AC31: Unidad
A32: PEY31 | B32: Papel parafinado | C32: Empaques | E32: Unidad | H32: 23.9 | M32: W100 | N32: Unidad | AC32: Unidad
A33: PEY32 | B33: Aluminio 300mt | C33: Empaques | E33: Unidad | H33: 251.33333 | M33: W100 | N33: Unidad | AC33: Unidad
A34: PEY33 | B34: Vinipel | C34: Empaques | E34: Unidad | H34: 135000 | M34: W100 | N34: Unidad | AC34: Unidad
A35: PEY34 | B35: Bolsa Camiseta 20 kilos | C35: Empaques | E35: Unidad | H35: 160 | M35: W100 | N35: Unidad | AC35: Unidad
A36: PEY35 | B36: Servilletas | C36: Empaques | E36: Unidad | H36: 29.616667 | M36: W100 | N36: Unidad | AC36: Unidad
A37: PEY36 | B37: Guantes Plasticos | C37: Otros | E37: Unidad | H37: 18.6 | M37: W100 | N37: Unidad | AC37: Unidad
A38: PEY37 | B38: Guantes Nitrilo | C38: Otros | E38: Unidad | H38: 320 | M38: W100 | N38: Unidad | AC38: Unidad
A39: PEY38 | B39: Tapabocas | C39: Otros | E39: Unidad | H39: 165 | M39: W100 | N39: Unidad | AC39: Unidad
... A78: PEY77 | B78: tapa 0,5 | C78: Empaques | E78: Unidad | H78: 80 | M78: W100 | N78: Unidad | AC78: Unidad
A79: PEY78 | B79: Tortilla de maiz 17x40 | C79: Cereales y harinas | E79: Unidad | H79: 20 | N79: Unidad | AC79: Unidad
...

Sheet PRODUCTOS PLANTA PRODUCCION
A1: Code | B1: Name | C1: Cod. Familia / Departamento | D1: Cant. Inventario | E1: Cod. Unidad | F1: Min | G1: Max | H1: Cost | I1: Bar Code | J1: Reorder Point | K1: R. Qty | L1: Waste | M1: Cod. Warehouse | N1: Presentacion del proveedor | O1: Costo Proveedor | P1: Producto Final? (Si,No) | Q1: Precio Venta | R1: Impuesto Item | S1: Cod. Categoria Item | T1: Cod. Item | U1: Cod. Autor | V1: Cod. Colección | W1: Activo? (Si/No) | X1: Descripcion | Y1: Precio Especial | Z1: Caracteristica1 | AA1: Venta Online Ecommerce? (Si/No) | AB1: Nombre de Imagen | AC1: Unidad de Inventario de Producto
A2: PR001 | B2: Carne de res (Descargue) | C2: Proteinas | E2: Gramos | H2: 22 | M2: W100 | N2: Gramos | O2: 12000 | P2: No | AC2: Gramos
A3: PR002 | B3: Panceta de cerdo | C3: Proteinas | E3: Gramos | H3: 27 | M3: W100 | N3: Gramos | O3: 8000 | P3: No | AC3: Gramos
A4: PR003 | B4: chicharrón | C4: Proteinas | E4: Gramos | H4: 36 | M4: W100 | N4: Gramos | O4: 20000 | P4: SI | AC4: Gramos
A5: PR004 | B5: Achiote | C5: Especias y condimentos | E5: Gramos | H5: 38 | M5: W100 | N5: Gramos | O5: 25000 | P5: No | AC5: Gramos
A6: PR005 | B6: Aji dulce | C6: Especias y condimentos | E6: Gramos | H6: 20.2 | M6: W100 | N6: Gramos | O6: 18500 | P6: No | AC6: Gramos
A7: PR006 | B7: Ajo | C7: Vegetales y Hortalizas | E7: Gramos | H7: 16 | M7: W100 | N7: Gramos | O7: 12000 | P7: No | AC7: Gramos
A8: PR007 | B8: Caldo de pollo | C8: Especias y condimentos | E8: Gramos | H8: 34 | M8: W100 | N8: Gramos | O8: 12000 | P8: No | AC8: Gramos
A9: PR008 | B9: Caldo de res | C9: Especias y condimentos | E9: Gramos | H9: 37 | M9: W100 | N9: Gramos | O9: 50000 | P9: No | AC9: Gramos
A10: PR009 | B10: Cebolla blanca | C10: Vegetales y Hortalizas | E10: Gramos | H10: 6 | M10: W100 | N10: Gramos | O10: 50000 | P10: No | AC10: Gramos
A11: PR010 | B11: Chile ancho | C11: Especias y condimentos | E11: Gramos | H11: 120 | M11: W100 | N11: Gramos | O11: 12000 | P11: No | AC11: Gramos
A12: PR011 | B12: Chile de arbol | C12: Especias y condimentos | E12: Gramos | H12: 135 | M12: W100 | N12: Gramos | O12: 2000 | P12: No | AC12: Gramos
A13: PR012 | B13: Chile guajillo | C13: Especias y condimentos | E13: Gramos | H13: 131 | M13: W100 | N13: Gramos | O13: 1000 | P13: No | AC13: Gramos
A14: PR013 | B14: Comino | C14: Especias y condimentos | E14: Gramos | H14: 60 | M14: W100 | N14: Gramos | AC14: Gramos
A15: PR014 | B15: Coriandro | C15: Especias y condimentos | E15: Gramos | H15: 44.03 | M15: W100 | N15: Gramos | AC15: Gramos
A16: PR015 | B16: Grasa de pecho | C16: Proteinas | E16: Gramos | H16: 8 | M16: W100 | N16: Gramos | AC16: Gramos
A17: PR016 | B17: tuetano de res | C17: Proteinas | E17: Gramos | H17: 5 | M17: W100 | N17: Gramos | AC17: Gramos
A18: PR017 | B18: hueso de res | C18: Proteinas | E18: Gramos | H18: 4 | M18: W100 | N18: Gramos | AC18: Gramos
A19: PR018 | B19: manteca de cerdo | C19: Proteinas | E19: Gramos | H19: 19 | M19: W100 | N19: Gramos | AC19: Gramos
A20: PR019 | B20: Laurel | C20: Vegetales y Hortalizas | E20: Gramos | H20: 18 | M20: W100 | N20: Gramos | AC20: Gramos
A21: PR020 | B21: canela en polvo | C21: Especias y condimentos | E21: Gramos | H21: 23 | M21: W100 | N21: Gramos | AC21: Gramos
A22: PR021 | B22: color amarillo | C22: Especias y condimentos | E22: Gramos | H22: 9 | M22: W100 | N22: Gramos | AC22: Gramos
A23: PR022 | B23: Oregano en escamas | C23: Especias y condimentos | E23: Gramos | H23: 31 | M23: W100 | N23: Gramos | AC23: Gramos
A24: PR023 | B24: Pimienta entera blanca | C24: Especias y condimentos | E24: Gramos | H24: 69 | M24: W100 | N24: Gramos | AC24: Gramos
A25: PR024 | B25: Pimienta entera negra | C25: Especias y condimentos | E25: Gramos | H25: 63 | M25: W100 | N25: Gramos | AC25: Gramos
... A73: PEY04 | B73: Bolsa capucha canastilla | C73: Empaques | E73: Unidad | H73: 400 | M73: W100 | N73: Unidad | AC73: Unidad
A74: PEY05 | B74: Bolsa Jumbo basura verde | C74: Otros | E74: Unidad | H74: 1580 | M74: W100 | N74: Unidad | P74: SI | AC74: Unidad
A75: PEY06 | B75: Bolsa jumbo bausra negra | C75: Otros | E75: Unidad | H75: 1580 | M75: W100 | N75: Unidad | P75: SI | AC75: Unidad
A76: PEY07 | B76: Rollo Industrial Cocina | C76: Otros | E76: Unidad | H76: 104000 | M76: W100 | N76: Unidad | P76: SI | AC76: Unidad
A77: PEY08 | B77: bolsa jumbo blanca | C77: Otros | E77: Unidad | H77: 1580 | M77: W100 | N77: Unidad | P77: SI | AC77: Unidad
A78: PEY09 | B78: bolsa baño negra | C78: Otros | E78: Unidad | H78: 1580 | M78: W100 | N78: Unidad | P78: SI | AC78: Unidad
A79: PR068 | B79: Color paprika | C79: Especias y condimentos | E79: mililitro | H79: 70 | M79: W100 | N79: mililitro | P79: NO | AC79: mililitro
A80: PR069 | B80: aceite fritol | C80: Aceites y grasas | E80: Gramos | H80: 9.9644 | M80: W100 | N80: mililitro | AC80: mililitro
A81: PR070 | B81: vinagre blanco | C81: Especias y condimentos | E81: mililitro | H81: 5 | M81: W100 | N81: mililitro | AC81: mililitro
A82: PR071 | B82: vinagre manzana | C82: Especias y condimentos | E82: mililitro | H82: 5 | M82: W100 | N82: mililitro | AC82: mililitro
A83: PR072 | B83: cebolla en polvo | C83: Especias y condimentos | E83: Gramos | H83: 26 | M83: W100 | N83: Gramos | AC83: Gramos
A84: PR073 | B84: sirope de maiz | C84: Especias y condimentos | E84: Gramos | H84: 52 | M84: W100 | N84: mililitro | AC84: mililitro
A85: PR074 | B85: caldo camaron | C85: Especias y condimentos | E85: Gramos | H85: 38 | M85: W100 | N85: Gramos | AC85: Gramos
A86: PR075 | B86: acido citrico | C86: Especias y condimentos | E86: Gramos | H86: 7 | M86: W100 | N86: Gramos | AC86: Gramos
A87: PR076 | B87: color fresa | C87: Especias y condimentos | E87: Gramos | H87: 20 | M87: W100 | N87: Gramos | AC87: Gramos
...

Sheet Items y Modificadores.
A1: Code | B1: Item Name | C1: Open Price? (Si/No) | D1: Sale Price | E1: Bar Code | F1: Category Code | G1: Sub-Category Name | H1: Category Name | I1: Tax | J1: Active? (Si/No) | K1: Commission | L1: Commission Type ($ / %) | M1: Special Price | N1: Allow Ecommerce Sale ? (Si/No) | O1: Ecommerce Sale Price | P1: Description | Q1: Photo Name | R1: Ecommerce Name | S1: Item Type (Normal, Gift Card, Certificado, Abono, Suscripcion, Domicilio, Tarifa de Cuarto) | T1: Ecommerce Category Code | U1: Ecommerce Category Name | V1: Integration Code | W1: Tax on Item | Y1: Modificador 1 | Z1: Opciones de Modificador 1 | AA1: Precio de modificadro 1 | AC1: Modificador 2 | AD1: Opciones de Modificador 2 | AE1: Precio de modificadro 2
A2: M1 | B2: Whisky Singleton | C2: NO | D2: 0 | E2: Whisky | F2: 0 | G2: Whisky | H2: Licores | I2: 7 | J2: 7 | K2: 7 | L2: 7 | M2: 7 | N2: 7 | O2: 7 | W2: 7 | Y2: Whisky Singleton | Z2: Trago | AA2: 12 | AC2: Opciond de Barra | AD2: Con Hielo | AE2: 0
A3: M1 | B3: Whisky Singleton | C3: NO | D3: 0 | G3: Whisky | H3: Licores | I3: 7 | W3: 7 | Y3: Whisky Singleton | Z3: Botella | AA3: 150 | AC3: Opciond de Barra | AD3: Sin Hielo | AE3: 0
A4: M2 | B4: Whisky Sello Negro | C4: NO | D4: 200 | E4: $ 0.00 | F4: Whisky | G4: Whisky | H4: Licores | I4: 7 | W4: 7
A5: M3 | B5: Whisky Macallan Dbcask 18 AÑos | C5: NO | D5: 130 | E5: $ 28,000,000.00 | F5: Whisky | G5: Whisky | H5: Licores | I5: 7 | W5: 7
A6: M4 | B6: Whisly Glenmorangie Quinta Ruba | C6: NO | D6: 80 | E6: $ 550,000.00 | F6: Whisky | G6: Whisky | H6: Licores | I6: 7 | W6: 7
A7: M5 | B7: Whisly Glenmorangie Original | C7: NO | D7: 125 | E7: $ 450,000.00 | F7: Whisky | G7: Whisky | H7: Licores | I7: 7 | W7: 7
A8: M6 | B8: Whisly Glenmorangie Nectar | C8: NO | D8: 120 | E8: $ 650,000.00 | G8: Whisky | H8: Licores | I8: 7 | W8: 7
A9: M7 | B9: Gin Tonic Tanqueray | C9: NO | D9: 12 | E9: Cócteles | F9: 0 | G9: Cocteles | H9: Licores | I9: 7 | W9: 7
A10: M8 | B10: Gin Tonic Hendrics | C10: NO | D10: 12 | E10: $ 55,000.00 | F10: Cócteles | G10: Cocteles | H10: Licores | I10: 7 | W10: 7
A11: M9 | B11: Margarita Premium 2x1 | C11: NO | D11: 12 | E11: $ 50,000.00 | F11: Cócteles | G11: Cocteles | H11: Licores | I11: 7 | W11: 7
A12: M10 | B12: Tizon Kiwi Lychee | C12: NO | D12: 12 | G12: Cocteles | H12: Licores | I12: 7 | W12: 7
A13: M11 | B13: Hamburguesa Especial | C13: NO | D13: 15 | G13: Platos Fuertes | H13: Menu Alimentos | I13: 7 | W13: 7

Sheet Subrecetas (Producciones.)
A2: Codigo | B2: Nombre de la Produccion | C2: Redimiento | D2: unidad | E2: Cod Ingrediente | F2: Ingredientes | G2: Cantidad | H2: Cantidad
A3: SB001 | B3: SALSA TAQUERA ROGELIO | C3: 15 | D3: Litro | E3: ='PRODUCTOS PLANTA PRODUCCION'!A33 -> PR032 | F3: ='PRODUCTOS PLANTA PRODUCCION'!B33 -> Tomatillo | G3: 5000 | H3: gramos
A4: SB001 | B4: SALSA TAQUERA ROGELIO | C4: 15 | D4: Litro | E4: ='PRODUCTOS PLANTA PRODUCCION'!A29 -> PR028 | F4: ='PRODUCTOS PLANTA PRODUCCION'!B29 -> Tomate chonto | G4: 5800 | H4: gramos
A5: SB001 | B5: SALSA TAQUERA ROGELIO | C5: 15 | D5: Litro | E5: ='PRODUCTOS PLANTA PRODUCCION'!A10 -> PR009 | F5: ='PRODUCTOS PLANTA PRODUCCION'!B10 -> Cebolla blanca | G5: 1700 | H5: gramos
A6: SB001 | B6: SALSA TAQUERA ROGELIO | C6: 15 | D6: Litro | E6: ='PRODUCTOS PLANTA PRODUCCION'!A12 -> PR011 | F6: ='PRODUCTOS PLANTA PRODUCCION'!B12 -> Chile de arbol | G6: 35 | H6: gramos
A7: SB001 | B7: SALSA TAQUERA ROGELIO | C7: 15 | D7: Litro | E7: ='PRODUCTOS PLANTA PRODUCCION'!A13 -> PR012 | F7: ='PRODUCTOS PLANTA PRODUCCION'!B13 -> Chile guajillo | G7: 186 | H7: gramos
A8: SB001 | B8: SALSA TAQUERA ROGELIO | C8: 15 | D8: Litro | E8: ='PRODUCTOS PLANTA PRODUCCION'!A35 -> PR034 | F8: ='PRODUCTOS PLANTA PRODUCCION'!B35 -> Chile morita | G8: 85 | H8: gramos
A9: SB001 | B9: SALSA TAQUERA ROGELIO | C9: 15 | D9: Litro | E9: ='PRODUCTOS PLANTA PRODUCCION'!A7 -> PR006 | F9: Ajo | G9: 420 | H9: gramos
A10: SB001 | B10: SALSA TAQUERA ROGELIO | C10: 15 | D10: Litro | E10: ='PRODUCTOS PLANTA PRODUCCION'!A28 -> PR027 | F10: ='PRODUCTOS PLANTA PRODUCCION'!B28 -> Sal común | G10: 250 | H10: gramos
A11: SB001 | B11: SALSA TAQUERA ROGELIO | C11: 15 | D11: Litro | E11: ='PRODUCTOS PLANTA PRODUCCION'!A96 -> PR082 | F11: ='PRODUCTOS PLANTA PRODUCCION'!B96 -> AGUA POTABLE | G11: 2000 | H11: Mililitro
A12: SB001 | B12: SALSA TAQUERA ROGELIO | C12: 15 | D12: Litro | E12: ='PRODUCTOS GENERALES PEYBU '!A2 -> PEY01 | F12: Bolsa plana flexible 43x41 | G12: 1 | H12: unidad
A15: SB002 | B15: SALSA PICANTE | C15: 11 | D15: Litro | E15: ='PRODUCTOS PLANTA PRODUCCION'!A29 -> PR028 | F15: ='PRODUCTOS PLANTA PRODUCCION'!B29 -> Tomate chonto | G15: 3900 | H15: gramos
A16: SB002 | B16: SALSA PICANTE | C16: 11 | D16: Litro | E16: ='PRODUCTOS PLANTA PRODUCCION'!A10 -> PR009 | F16: Cebolla blanca | G16: 1750 | H16: gramos
A17: SB002 | B17: SALSA PICANTE | C17: 11 | D17: Litro | E17: ='PRODUCTOS PLANTA PRODUCCION'!A36 -> PR035 | F17: ='PRODUCTOS PLANTA PRODUCCION'!B36 -> Chile serrano | G17: 320 | H17: gramos
A18: SB002 | B18: SALSA PICANTE | C18: 11 | D18: Litro | E18: ='PRODUCTOS PLANTA PRODUCCION'!A37 -> PR036 | F18: ='PRODUCTOS PLANTA PRODUCCION'!B37 -> Chile abanero | G18: 500 | H18: gramos
A19: SB002 | B19: SALSA PICANTE | C19: 11 | D19: Litro | E19: PRO33 | F19: Chile morita | G19: 140 | H19: gramos
A20: SB002 | B20: SALSA PICANTE | C20: 11 | D20: Litro | E20: ='PRODUCTOS PLANTA PRODUCCION'!A6 -> PR005 | F20: ='PRODUCTOS PLANTA PRODUCCION'!B6 -> Aji dulce | G20: 640 | H20: gramos
A21: SB002 | B21: SALSA PICANTE | C21: 11 | D21: Litro | E21: ='PRODUCTOS PLANTA PRODUCCION'!A7 -> PR006 | F21: ajo | G21: 280 | H21: gramos
A22: SB002 | B22: SALSA PICANTE | C22: 11 | D22: Litro | E22: ='PRODUCTOS PLANTA PRODUCCION'!A28 -> PR027 | F22: sal comun | G22: 250 | H22: gramos
A23: SB002 | B23: SALSA PICANTE | C23: 11 | D23: Litro | E23: ='PRODUCTOS PLANTA PRODUCCION'!A96 -> PR082 | F23: AGUA POTABLE | G23: 3500 | H23: Mililitro
A24: SB002 | B24: SALSA PICANTE | C24: 11 | D24: Litro | E24: PEY01 | F24: Bolsa plana flexible 43x41 | G24: 1 | H24: unidad
A26: SB003 | B26: SALA TAQUERA AUTOCAR | C26: 5 | D26: Litro | E26: ='PRODUCTOS PLANTA PRODUCCION'!A34 -> PR033 | F26: ='PRODUCTOS PLANTA PRODUCCION'!B34 -> Jalapeño verde | G26: 250 | H26: gramos
A27: SB003 | B27: SALA TAQUERA AUTOCAR | C27: 5 | D27: Litro | E27: PR008 | F27: Cebolla blanca | G27: 500 | H27: gramos
A28: SB003 | B28: SALA TAQUERA AUTOCAR | C28: 5 | D28: Litro | E28: PR005 | F28: ajo | G28: 280 | H28: gramos
A29: SB003 | B29: SALA TAQUERA AUTOCAR | C29: 5 | D29: Litro | E29: ='PRODUCTOS PLANTA PRODUCCION'!A11 -> PR010 | F29: Chile ancho | G29: 140 | H29: gramos
A30: SB003 | B30: SALA TAQUERA AUTOCAR | C30: 5 | D30: Litro | E30: ='PRODUCTOS PLANTA PRODUCCION'!A33 -> PR032 | F30: Tomatillo | G30: 1000 | H30: gramos
A31: SB003 | B31: SALA TAQUERA AUTOCAR | C31: 5 | D31: Litro | E31: ='PRODUCTOS PLANTA PRODUCCION'!A29 -> PR028 | F31: Tomate Chonto | G31: 3000 | H31: gramos
A32: SB003 | B32: SALA TAQUERA AUTOCAR | C32: 5 | D32: Litro | E32: ='PRODUCTOS PLANTA PRODUCCION'!A97 -> PR083 | F32: aceite oliva | G32: 120 | H32: mililitros
A33: SB003 | B33: SALA TAQUERA AUTOCAR | C33: 5 | D33: Litro | E33: ='PRODUCTOS PLANTA PRODUCCION'!A28 -> PR027 | F33: sal comun | G33: 3 | H33: gramos
A34: SB003 | B34: SALA TAQUERA AUTOCAR | C34: 5 | D34: Litro | E34: ='PRODUCTOS PLANTA PRODUCCION'!A27 -> PR026 | F34: Pimienta moilda | G34: 36 | H34: gramos
A35: SB003 | B35: SALA TAQUERA AUTOCAR | C35: 5 | D35: Litro | E35: PEY02 | F35: bolsa planaflexible 32x36 | G35: 1 | H35: unidad
A38: SB004 | B38: SALSA VERDE | C38: 4 | D38: Litro | E38: ='PRODUCTOS PLANTA PRODUCCION'!A34 -> PR033 | F38: Jalapeño verde | G38: 3150 | H38: gramos
A39: SB004 | B39: SALSA VERDE | C39: 4 | D39: Litro | E39: PR008 | F39: Cebolla Blanca | G39: 700 | H39: gramos
A40: SB004 | B40: SALSA VERDE | C40: 4 | D40: Litro | E40: PR005 | F40: Ajo | G40: 155 | H40: gramos
A41: SB004 | B41: SALSA VERDE | C41: 4 | D41: Litro | E41: PR026 | F41: Sal | G41: 35 | H41: gramos
A42: SB004 | B42: SALSA VERDE | C42: 4 | D42: Litro | E42: PR025 | F42: Pimienta molida | G42: 15 | H42: gramos
A43: SB004 | B43: SALSA VERDE | C43: 4 | D43: Litro | E43: PRO83 | F43: Aceite oliva | G43: 40 | H43: mililitros
A44: SB004 | B44: SALSA VERDE | C44: 4 | D44: Litro | E44: PR082 | F44: agua | G44: 200 | H44: mililitros
A45: SB004 | B45: SALSA VERDE | C45: 4 | D45: Litro | E45: PEY02 | F45: bolsa planaflexible 32x36 | G45: 1 | H45: unidad
A48: SB005 | B48: SALSA ROJA | C48: 9 | D48: Litros | E48: ='PRODUCTOS PLANTA PRODUCCION'!A12 -> PR011 | F48: chile de arbol | G48: 100 | H48: gramos
...

Sheet Recetas.
A1: Codigo de Items | B1: Nombre de Items | C1: Codigo Producto | D1: Productos y Producciones | E1: Cantidad | F1: Unidad | G1: MARCA | H1: OBSERVACION
B2: Agua en Botella | C2: PEY27 | D2: Agua en botella | E2: 1 | F2: unidad | G2: TODAS
B3: Budweiser | C3: ='PRODUCTOS GENERALES PEYBU '!A29 -> PEY28 | D3: cerveza en lata | E3: 1 | F3: unidad | G3: TODAS
B4: Coca cola Normal | C4: PEY29 | D4: Gaseosa pet | E4: 1 | F4: unidad | G4: TODAS
B5: Coca cola Zero | C5: PEY29 | D5: Gaseosa pet | E5: 1 | F5: unidad | G5: TODAS
B6: Ginger | C6: PEY29 | D6: Gaseosa pet | E6: 1 | F6: unidad | G6: TODAS
A7: Bebida de la casa | B7: Horchata | C7: SUB016 | D7: horchata produccion | E7: 650 | F7: ml | G7: TODAS
B8: Horchata | C8: PEY41 | D8: Vasos 22 Oz gold | E8: 1 | F8: unidad | G8: TODAS
B9: Horchata | C9: PEY42 | D9: Tapas vaso Gold | E9: 1 | F9: unidad | G9: TODAS | H9: cuando es para llevar
A10: Bebida de la casa | B10: Jamaica | C10: SUB014 | D10: Jamaica produccion | E10: 650 | F10: ml | G10: TODAS
B11: Jamaica | C11: PEY41 | D11: Vasos 22 Oz gold | E11: 1 | F11: unidad | G11: TODAS
B12: Jamaica | C12: PEY42 | D12: Tapas vaso Gold | E12: 1 | F12: unidad | G12: TODAS | H12: cuando es para llevar
A13: Bebida de la casa | B13: Tamarindo | C13: SUB015 | D13: Tamarindo Producción | E13: 650 | F13: ml | G13: TODAS
B14: Tamarindo | C14: PEY41 | D14: Vasos 22 Oz gold | E14: 1 | F14: unidad | G14: TODAS
B15: Tamarindo | C15: PEY42 | D15: Tapas vaso Gold | E15: 1 | F15: unidad | G15: TODAS | H15: cuando es para llevar
A16: Bebida de la casa | B16: Michelada | C16: SUB07 | D16: Chamoy | E16: 27 | F16: gramos | G16: Rogelio red
B17: Michelada | C17: SUB08 | D17: Clamato | E17: 105 | F17: mililitros | G17: Rogelio red
B18: Michelada | C18: PEY24 | D18: sal de chamoy | E18: 4 | F18: gramos | G18: Rogelio red
B19: Michelada | C19: PEY18 | D19: Limón Taithy | E19: 25 | F19: gramos | G19: Rogelio red
B20: Michelada | C20: PEY22 | D20: Tabasco | E20: 0.5 | F20: mililitros | G20: Rogelio red
B21: Michelada | C21: PEY23 | D21: salsa ingelsa fresh | E21: 25 | F21: mililitros | G21: Rogelio red
B22: Michelada | C22: PEY41 | D22: Vasos 22 Oz gold | E22: 1 | F22: unidad | G22: Rogelio red
B23: Michelada | C23: PEY42 | D23: Tapas vaso Gold | E23: 1 | F23: unidad | G23: Rogelio red | H23: cuando es para llevar
B24: Michelada | C24: PEY26 | D24: Basukazo | E24: 1 | F24: unidad | G24: Rogelio red
B25: Michelada | C25: PEY25 | D25: Cerveza club colombia dorada 473 ml | E25: 1 | F25: unidad | G25: Rogelio red
A26: Adiciones | B26: Salsa picante | C26: PEY48 | D26: Scoop 2 onza carton | E26: 1 | F26: unidad | G26: Rogelio red
B27: Salsa picante | C27: PEY49 | D27: Tapa scoop 2 onzas | E27: 1 | F27: unidad | G27: Rogelio red | H27: cuando es para llevar
B28: Salsa picante | C28: SB002 | D28: SALSA PICANTE | E28: 45 | F28: mililitros | G28: Rogelio red
A29: Adiciones | B29: Porcion de tortilla | C29: PEY11 | D29: Tortillas Maíz 11x40 | E29: 3 | F29: unidad | G29: Rogelio red
B30: Porcion de tortilla | C30: PEY15 | D30: Tortillas fresca Maíz 11x32 autocar | E30: 3 | F30: unidad | G30: Autocar al pastor
B31: Adicion queso | C31: PEY80 | D31: Queso costeño | E31: 50 | F31: gramos | G31: ChayitoEsquites
B32: Adicion queso | C32: PEY48 | D32: Scoop 2 onza carton | E32: 1 | F32: unidad | G32: ChayitoEsquites
B33: Adicion queso | C33: PEY49 | D33: Tapa scoop 2 onzas | E33: 1 | F33: unidad | G33: ChayitoEsquites | H33: cuando es para llevar
B34: Adicion Chicharrón | C34: PR003 | D34: chicharrón | E34: 50 | F34: gramos | G34: ChayitoEsquites
B35: Adicion Chicharrón | C35: PEY48 | D35: Scoop 2 onza carton | E35: 1 | F35: unidad | G35: ChayitoEsquites
B36: Adicion Chicharrón | C36: PEY49 | D36: Tapa scoop 2 onzas | E36: 1 | F36: unidad | G36: ChayitoEsquites | H36: cuando es para llevar
B37: Caldo 8 onzas | C37: SB011 | D37: CALDO BIRRIA | E37: 240 | F37: mililitros | G37: Rogelio red
B38: Caldo 8 onzas | C38: PEY50 | D38: Sopero de 8 onzas carton | E38: 1 | F38: unidad | G38: Rogelio red
B39: Caldo 8 onzas | C39: PEY51 | D39: Tapa sopero 8 onzas | E39: 1 | F39: unidad | G39: Rogelio red
A40: Platos Principales | B40: vampiro | C40: PEY11 | D40: Tortillas Maíz 11x40 | E40: 1 | F40: unidad | G40: Rogelio red
...
